2024-01-19 16:44:58,900 INFO: Aplicaciï¿½ iniciada [in C:\Users\oscar\OneDrive\Escritorio\DAW2\m12-projecte\wannapop\__init__.py:55]
2024-01-19 16:44:58,911 INFO: Aplicaciï¿½ iniciada [in C:\Users\oscar\OneDrive\Escritorio\DAW2\m12-projecte\wannapop\__init__.py:55]
2024-01-19 16:44:58,911 INFO: Aplicaciï¿½ iniciada [in C:\Users\oscar\OneDrive\Escritorio\DAW2\m12-projecte\wannapop\__init__.py:55]
2024-01-19 16:44:59,553 INFO: Aplicaciï¿½ iniciada [in C:\Users\oscar\OneDrive\Escritorio\DAW2\m12-projecte\wannapop\__init__.py:55]
2024-01-19 16:44:59,564 INFO: Aplicaciï¿½ iniciada [in C:\Users\oscar\OneDrive\Escritorio\DAW2\m12-projecte\wannapop\__init__.py:55]
2024-01-19 16:44:59,564 INFO: Aplicaciï¿½ iniciada [in C:\Users\oscar\OneDrive\Escritorio\DAW2\m12-projecte\wannapop\__init__.py:55]
2024-01-19 16:45:03,074 INFO: Intent d'inici de sessiï¿½ [in C:\Users\oscar\OneDrive\Escritorio\DAW2\m12-projecte\wannapop\routes_auth.py:52]
2024-01-19 16:45:03,074 INFO: Intent d'inici de sessiï¿½ [in C:\Users\oscar\OneDrive\Escritorio\DAW2\m12-projecte\wannapop\routes_auth.py:52]
2024-01-19 16:45:05,431 INFO: Accï¿½s a la pï¿½gina principal [in C:\Users\oscar\OneDrive\Escritorio\DAW2\m12-projecte\wannapop\routes_main.py:20]
2024-01-19 16:45:05,431 INFO: Accï¿½s a la pï¿½gina principal [in C:\Users\oscar\OneDrive\Escritorio\DAW2\m12-projecte\wannapop\routes_main.py:20]
2024-01-19 16:45:11,098 INFO: Intent d'inici de sessiï¿½ [in C:\Users\oscar\OneDrive\Escritorio\DAW2\m12-projecte\wannapop\routes_auth.py:52]
2024-01-19 16:45:11,098 INFO: Intent d'inici de sessiï¿½ [in C:\Users\oscar\OneDrive\Escritorio\DAW2\m12-projecte\wannapop\routes_auth.py:52]
2024-01-19 16:46:20,535 INFO: Accï¿½s a la pï¿½gina principal [in C:\Users\oscar\OneDrive\Escritorio\DAW2\m12-projecte\wannapop\routes_main.py:20]
2024-01-19 16:46:20,535 INFO: Accï¿½s a la pï¿½gina principal [in C:\Users\oscar\OneDrive\Escritorio\DAW2\m12-projecte\wannapop\routes_main.py:20]
2024-01-19 16:46:55,846 INFO: Accï¿½s a la pï¿½gina d'administraciï¿½ d'usuaris [in C:\Users\oscar\OneDrive\Escritorio\DAW2\m12-projecte\wannapop\routes_admin.py:32]
2024-01-19 16:46:55,846 INFO: Accï¿½s a la pï¿½gina d'administraciï¿½ d'usuaris [in C:\Users\oscar\OneDrive\Escritorio\DAW2\m12-projecte\wannapop\routes_admin.py:32]
2024-01-19 16:47:01,326 INFO: Accï¿½s a la pï¿½gina d'administraciï¿½ d'usuaris [in C:\Users\oscar\OneDrive\Escritorio\DAW2\m12-projecte\wannapop\routes_admin.py:32]
2024-01-19 16:47:01,326 INFO: Accï¿½s a la pï¿½gina d'administraciï¿½ d'usuaris [in C:\Users\oscar\OneDrive\Escritorio\DAW2\m12-projecte\wannapop\routes_admin.py:32]
2024-01-19 16:47:02,670 INFO: Accï¿½s a la pï¿½gina d'administraciï¿½ d'usuaris [in C:\Users\oscar\OneDrive\Escritorio\DAW2\m12-projecte\wannapop\routes_admin.py:32]
2024-01-19 16:47:02,670 INFO: Accï¿½s a la pï¿½gina d'administraciï¿½ d'usuaris [in C:\Users\oscar\OneDrive\Escritorio\DAW2\m12-projecte\wannapop\routes_admin.py:32]
2024-01-19 16:48:40,444 INFO: Accï¿½s a la pï¿½gina d'administraciï¿½ d'usuaris [in C:\Users\oscar\OneDrive\Escritorio\DAW2\m12-projecte\wannapop\routes_admin.py:32]
2024-01-19 16:48:40,444 INFO: Accï¿½s a la pï¿½gina d'administraciï¿½ d'usuaris [in C:\Users\oscar\OneDrive\Escritorio\DAW2\m12-projecte\wannapop\routes_admin.py:32]
2024-01-19 17:05:01,653 INFO: Aplicació iniciada [in C:\Users\oscar\OneDrive\Escritorio\DAW2\m12-projecte\wannapop\__init__.py:55]
2024-01-19 17:05:01,663 INFO: Aplicació iniciada [in C:\Users\oscar\OneDrive\Escritorio\DAW2\m12-projecte\wannapop\__init__.py:55]
2024-01-19 17:05:01,663 INFO: Aplicació iniciada [in C:\Users\oscar\OneDrive\Escritorio\DAW2\m12-projecte\wannapop\__init__.py:55]
2024-01-19 17:05:08,050 INFO: Accés a la pàgina principal [in C:\Users\oscar\OneDrive\Escritorio\DAW2\m12-projecte\wannapop\routes_main.py:20]
2024-01-19 17:05:08,050 INFO: Accés a la pàgina principal [in C:\Users\oscar\OneDrive\Escritorio\DAW2\m12-projecte\wannapop\routes_main.py:20]
2024-01-19 17:05:12,907 ERROR: Exception on /products/read/5 [GET] [in C:\Users\oscar\AppData\Local\Programs\Python\Python310\lib\site-packages\flask\app.py:1414]
Traceback (most recent call last):
  File "C:\Users\oscar\AppData\Local\Programs\Python\Python310\lib\site-packages\flask\app.py", line 2190, in wsgi_app
    response = self.full_dispatch_request()
  File "C:\Users\oscar\AppData\Local\Programs\Python\Python310\lib\site-packages\flask\app.py", line 1486, in full_dispatch_request
    rv = self.handle_user_exception(e)
  File "C:\Users\oscar\AppData\Local\Programs\Python\Python310\lib\site-packages\flask\app.py", line 1484, in full_dispatch_request
    rv = self.dispatch_request()
  File "C:\Users\oscar\AppData\Local\Programs\Python\Python310\lib\site-packages\flask_debugtoolbar\__init__.py", line 157, in dispatch_request
    return view_func(**req.view_args)
  File "C:\Users\oscar\AppData\Local\Programs\Python\Python310\lib\site-packages\flask_login\utils.py", line 290, in decorated_view
    return current_app.ensure_sync(func)(*args, **kwargs)
  File "C:\Users\oscar\AppData\Local\Programs\Python\Python310\lib\site-packages\flask_principal.py", line 199, in _decorated
    rv = f(*args, **kw)
  File "C:\Users\oscar\OneDrive\Escritorio\DAW2\m12-projecte\wannapop\routes_main.py", line 89, in product_read
    current_app.logger.debug(item.to_json())
NameError: name 'item' is not defined
2024-01-19 17:05:12,907 ERROR: Exception on /products/read/5 [GET] [in C:\Users\oscar\AppData\Local\Programs\Python\Python310\lib\site-packages\flask\app.py:1414]
Traceback (most recent call last):
  File "C:\Users\oscar\AppData\Local\Programs\Python\Python310\lib\site-packages\flask\app.py", line 2190, in wsgi_app
    response = self.full_dispatch_request()
  File "C:\Users\oscar\AppData\Local\Programs\Python\Python310\lib\site-packages\flask\app.py", line 1486, in full_dispatch_request
    rv = self.handle_user_exception(e)
  File "C:\Users\oscar\AppData\Local\Programs\Python\Python310\lib\site-packages\flask\app.py", line 1484, in full_dispatch_request
    rv = self.dispatch_request()
  File "C:\Users\oscar\AppData\Local\Programs\Python\Python310\lib\site-packages\flask_debugtoolbar\__init__.py", line 157, in dispatch_request
    return view_func(**req.view_args)
  File "C:\Users\oscar\AppData\Local\Programs\Python\Python310\lib\site-packages\flask_login\utils.py", line 290, in decorated_view
    return current_app.ensure_sync(func)(*args, **kwargs)
  File "C:\Users\oscar\AppData\Local\Programs\Python\Python310\lib\site-packages\flask_principal.py", line 199, in _decorated
    rv = f(*args, **kw)
  File "C:\Users\oscar\OneDrive\Escritorio\DAW2\m12-projecte\wannapop\routes_main.py", line 89, in product_read
    current_app.logger.debug(item.to_json())
NameError: name 'item' is not defined
2024-01-19 17:05:15,067 ERROR: Exception on /products/read/8 [GET] [in C:\Users\oscar\AppData\Local\Programs\Python\Python310\lib\site-packages\flask\app.py:1414]
Traceback (most recent call last):
  File "C:\Users\oscar\AppData\Local\Programs\Python\Python310\lib\site-packages\flask\app.py", line 2190, in wsgi_app
    response = self.full_dispatch_request()
  File "C:\Users\oscar\AppData\Local\Programs\Python\Python310\lib\site-packages\flask\app.py", line 1486, in full_dispatch_request
    rv = self.handle_user_exception(e)
  File "C:\Users\oscar\AppData\Local\Programs\Python\Python310\lib\site-packages\flask\app.py", line 1484, in full_dispatch_request
    rv = self.dispatch_request()
  File "C:\Users\oscar\AppData\Local\Programs\Python\Python310\lib\site-packages\flask_debugtoolbar\__init__.py", line 157, in dispatch_request
    return view_func(**req.view_args)
  File "C:\Users\oscar\AppData\Local\Programs\Python\Python310\lib\site-packages\flask_login\utils.py", line 290, in decorated_view
    return current_app.ensure_sync(func)(*args, **kwargs)
  File "C:\Users\oscar\AppData\Local\Programs\Python\Python310\lib\site-packages\flask_principal.py", line 199, in _decorated
    rv = f(*args, **kw)
  File "C:\Users\oscar\OneDrive\Escritorio\DAW2\m12-projecte\wannapop\routes_main.py", line 89, in product_read
    current_app.logger.debug(item.to_json())
NameError: name 'item' is not defined
2024-01-19 17:05:15,067 ERROR: Exception on /products/read/8 [GET] [in C:\Users\oscar\AppData\Local\Programs\Python\Python310\lib\site-packages\flask\app.py:1414]
Traceback (most recent call last):
  File "C:\Users\oscar\AppData\Local\Programs\Python\Python310\lib\site-packages\flask\app.py", line 2190, in wsgi_app
    response = self.full_dispatch_request()
  File "C:\Users\oscar\AppData\Local\Programs\Python\Python310\lib\site-packages\flask\app.py", line 1486, in full_dispatch_request
    rv = self.handle_user_exception(e)
  File "C:\Users\oscar\AppData\Local\Programs\Python\Python310\lib\site-packages\flask\app.py", line 1484, in full_dispatch_request
    rv = self.dispatch_request()
  File "C:\Users\oscar\AppData\Local\Programs\Python\Python310\lib\site-packages\flask_debugtoolbar\__init__.py", line 157, in dispatch_request
    return view_func(**req.view_args)
  File "C:\Users\oscar\AppData\Local\Programs\Python\Python310\lib\site-packages\flask_login\utils.py", line 290, in decorated_view
    return current_app.ensure_sync(func)(*args, **kwargs)
  File "C:\Users\oscar\AppData\Local\Programs\Python\Python310\lib\site-packages\flask_principal.py", line 199, in _decorated
    rv = f(*args, **kw)
  File "C:\Users\oscar\OneDrive\Escritorio\DAW2\m12-projecte\wannapop\routes_main.py", line 89, in product_read
    current_app.logger.debug(item.to_json())
NameError: name 'item' is not defined
2024-01-19 17:05:34,751 INFO: Accés a la pàgina principal [in C:\Users\oscar\OneDrive\Escritorio\DAW2\m12-projecte\wannapop\routes_main.py:20]
2024-01-19 17:05:34,751 INFO: Accés a la pàgina principal [in C:\Users\oscar\OneDrive\Escritorio\DAW2\m12-projecte\wannapop\routes_main.py:20]
2024-01-19 17:08:44,195 INFO: Accés a la pàgina principal [in C:\Users\oscar\OneDrive\Escritorio\DAW2\m12-projecte\wannapop\routes_main.py:20]
